<?xml version='1.0'?>
<sdf version='1.4'>
  <model name="my_robot">

    <static>false</static>

    <!-- Chassis Link -->
    <link name='chassis'>
      <pose>0 0 .1 0 0 0</pose>
      <!-- 질량 및 관성 요소 추가 -->
      <inertial>
        <mass>10.0</mass>        <!-- 질량 설정 -->
        <inertia>
          <ixx>0.1</ixx>
          <ixy>0.0</ixy>
          <ixz>0.0</ixz>
          <iyy>0.1</iyy>
          <iyz>0.0</iyz>
          <izz>0.1</izz>
        </inertia>
      </inertial>
      <collision name='collision'>
        <geometry>
          <box>
            <size>.5 .3 .1</size>
          </box>
        </geometry>
      </collision>
      <visual name='visual'>
        <geometry>
          <box>
            <size>.5 .3 .1</size>
          </box>
        </geometry>
      </visual>
    </link>

    <!-- rear left Wheel Link -->
    <link name="rear_left_wheel">
      <pose>.2 .175 .1 1.5708 0 0</pose>
      <!-- 질량 및 관성 요소 추가 -->
      <inertial>
        <mass>0.5</mass>        <!-- 질량 설정 -->
        <inertia>
          <ixx>0.01</ixx>
          <ixy>0.0</ixy>
          <ixz>0.0</ixz>
          <iyy>0.01</iyy>
          <iyz>0.0</iyz>
          <izz>0.01</izz>
        </inertia>
      </inertial>
      <collision name="collision">
        <geometry>
          <cylinder>
            <radius>.1</radius>
            <length>.05</length>
          </cylinder>
        </geometry>
      </collision>
      <surface>
        <friction>
          <ode>
            <mu>1.0</mu>
            <mu2>1.0</mu2>
          </ode>
        </friction>
      </surface>
      <visual name="visual">
        <geometry>
          <cylinder>
            <radius>.1</radius>
            <length>.05</length>
          </cylinder>
        </geometry>
      </visual>
    </link>

    <!-- Joint_rear_left -->
    <joint name="joint_rl" type="revolute">
      <pose>0 0 .025 0 0 0</pose>
      <parent>chassis</parent>
      <child>rear_left_wheel</child>
      <axis>
        <xyz>0 1 0</xyz>
      </axis>
    </joint>

    <!-- rear right Wheel Link -->
    <link name="rear_right_wheel">
      <pose>.2 -.175 .1 1.5708 0 0</pose>
      <!-- 질량 및 관성 요소 추가 -->
      <inertial>
        <mass>0.5</mass>        <!-- 질량 설정 -->
        <inertia>
          <ixx>0.01</ixx>
          <ixy>0.0</ixy>
          <ixz>0.0</ixz>
          <iyy>0.01</iyy>
          <iyz>0.0</iyz>
          <izz>0.01</izz>
        </inertia>
      </inertial>
      <collision name="collision">
        <geometry>
          <cylinder>
            <radius>.1</radius>
            <length>.05</length>
          </cylinder>
        </geometry>
      </collision>
      <surface>
        <friction>
          <ode>
            <mu>1.0</mu>
            <mu2>1.0</mu2>
          </ode>
        </friction>
      </surface>
      <visual name="visual">
        <geometry>
          <cylinder>
            <radius>.1</radius>
            <length>.05</length>
          </cylinder>
        </geometry>
      </visual>
    </link>

    <!-- Joint_rear_right -->
    <joint name="joint_rr" type="revolute">
      <pose>0 0 -.025 0 0 0</pose>
      <parent>chassis</parent>
      <child>rear_right_wheel</child>
      <axis>
        <xyz>0 1 0</xyz>
      </axis>
    </joint>

    <!-- front left Wheel Link -->
    <link name="front_left_wheel">
      <pose>-.2 .175 .1 1.5708 0 0</pose>
      <!-- 질량 및 관성 요소 추가 -->
      <inertial>
        <mass>0.5</mass>        <!-- 질량 설정 -->
        <inertia>
          <ixx>0.01</ixx>
          <ixy>0.0</ixy>
          <ixz>0.0</ixz>
          <iyy>0.01</iyy>
          <iyz>0.0</iyz>
          <izz>0.01</izz>
        </inertia>
      </inertial>
      <collision name="collision">
        <geometry>
          <cylinder>
            <radius>.1</radius>
            <length>.05</length>
          </cylinder>
        </geometry>
      </collision>
      <surface>
        <friction>
          <ode>
            <mu>1.0</mu>
            <mu2>1.0</mu2>
          </ode>
        </friction>
      </surface>
      <visual name="visual">
        <geometry>
          <cylinder>
            <radius>.1</radius>
            <length>.05</length>
          </cylinder>
        </geometry>
      </visual>
    </link>

    <!-- Joint_front_left -->
    <joint name="joint_fl" type="revolute">
      <pose>0 0 .025 0 0 0</pose>
      <parent>chassis</parent>
      <child>front_left_wheel</child>
      <axis>
        <xyz>0 1 0</xyz>
      </axis>
    </joint>

    <!-- front right Wheel Link -->
    <link name="front_right_wheel">
      <pose>-.2 -.175 .1 1.5708 0 0</pose>
      <!-- 질량 및 관성 요소 추가 -->
      <inertial>
        <mass>0.5</mass>        <!-- 질량 설정 -->
        <inertia>
          <ixx>0.01</ixx>
          <ixy>0.0</ixy>
          <ixz>0.0</ixz>
          <iyy>0.01</iyy>
          <iyz>0.0</iyz>
          <izz>0.01</izz>
        </inertia>
      </inertial>
      <collision name="collision">
        <geometry>
          <cylinder>
            <radius>.1</radius>
            <length>.05</length>
          </cylinder>
        </geometry>
      </collision>
      <surface>
        <friction>
          <ode>
            <mu>1.0</mu>
            <mu2>1.0</mu2>
          </ode>
        </friction>
      </surface>
      <visual name="visual">
        <geometry>
          <cylinder>
            <radius>.1</radius>
            <length>.05</length>
          </cylinder>
        </geometry>
      </visual>
    </link>

    <!-- Joint_front_right -->
    <joint name="joint_fr" type="revolute">
      <pose>0 0 -.025 0 0 0</pose>
      <parent>chassis</parent>
      <child>front_right_wheel</child>
      <axis>
        <xyz>0 1 0</xyz>
      </axis>
    </joint>


    <!-- manipulator -->
    <!-- <link name="base_link">
      <pose>0 0 0.175 0 0 0</pose>
      <visual name="visual">
        <geometry>
          <cylinder>
            <radius>.1</radius>
            <length>.05</length>
          </cylinder>
        </geometry>
      </visual>
      <collision name="collision">
        <geometry>
          <cylinder>
            <radius>.1</radius>
            <length>.05</length>
          </cylinder>
        </geometry>
      </collision>
    </link> -->

    <!-- Joint 1 -->
    <!-- <joint name="joint1" type="revolute">
      <parent>chassis</parent>
      <child>base_link</child>
      <pose>0 0 -0.025 0 0 0</pose>
      <axis>
        <xyz>0 0 1</xyz>
        <limit>
          <lower>0.0</lower>
          <upper>1.57</upper>
        </limit>
        <dynamics>
          <damping>0.1</damping>
          <friction>0.1</friction>
        </dynamics>
      </axis>
    </joint> -->

    <!-- link 1 -->
    <!-- <link name="link1">
      <pose>0 0 0.225 0 0 0</pose>
      <visual name="visual">
        <geometry>
          <box>
            <size>.06 .06 .05</size>
          </box>
        </geometry>
      </visual>
      <collision name="collision">
        <geometry>
          <box>
            <size>.06 .06 .05</size>
          </box>
        </geometry>
      </collision>
    </link> -->

    <!-- Joint_connection_1 -->
    <!-- <joint name="joint_c1" type="fixed">
      <parent>base_link</parent>
      <child>link1</child>
      <pose>0 0 -0.025 0 0 0</pose>
    </joint> -->

    <!-- connection_1 -->
    <!-- <link name="connection1">
      <pose>0 0 0.28 1.5708 0 0</pose>
      <visual name="visual">
        <geometry>
          <cylinder>
            <radius>.03</radius>
            <length>.06</length>
          </cylinder>
        </geometry>
      </visual>
      <collision name="collision">
        <geometry>
          <cylinder>
            <radius>.03</radius>
            <length>.06</length>
          </cylinder>
        </geometry>
      </collision>
    </link> -->

    <!-- Joint_connection_2 -->
    <!-- <joint name="joint_c2" type="fixed">
      <parent>link1</parent>
      <child>connection1</child>
      <pose>0 -0.035 0 0 0 0 0</pose>
    </joint> -->


    <!-- link 2 -->
    <!-- <link name="link2">
      <pose>0 0 0.385 0 0 0</pose>
      <visual name="visual">
        <geometry>
          <box>
            <size>.06 .06 .15</size>
          </box>
        </geometry>
      </visual>
      <collision name="collision">
        <geometry>
          <box>
            <size>.06 .06 .15</size>
          </box>
        </geometry>
      </collision>
    </link> -->

    <!-- Joint 2 -->
    <!-- <joint name="joint2" type="revolute">
      <parent>link2</parent>
      <child>connection1</child>
      <pose>0 0 0 0 0 0</pose>
      <axis>
        <xyz>0 1 0</xyz>
        <limit>
          <lower>0.0</lower>
          <upper>1.57</upper>
        </limit>
        <dynamics>
          <damping>0.1</damping>
          <friction>0.1</friction>
        </dynamics>
      </axis>
    </joint> -->

    <!-- connection_2 -->
    <!-- <link name="connection2">
      <pose>0 0 0.49 1.5708 0 0</pose>
      <visual name="visual">
        <geometry>
          <cylinder>
            <radius>.03</radius>
            <length>.06</length>
          </cylinder>
        </geometry>
      </visual>
      <collision name="collision">
        <geometry>
          <cylinder>
            <radius>.03</radius>
            <length>.06</length>
          </cylinder>
        </geometry>
      </collision>
    </link> -->

    <!-- Joint_connection_3 -->
    <!-- <joint name="joint_c3" type="fixed">
      <parent>link2</parent>
      <child>connection2</child>
      <pose>0 -0.035 0 0 0 0 0</pose>
    </joint> -->


    <!-- link 3 -->
    <!-- <link name="link3">
      <pose>0 0 0.595 0 0 0</pose>
      <visual name="visual">
        <geometry>
          <box>
            <size>.06 .06 .15</size>
          </box>
        </geometry>
      </visual>
      <collision name="collision">
        <geometry>
          <box>
            <size>.06 .06 .15</size>
          </box>
        </geometry>
      </collision>
    </link> -->

    <!-- Joint 3 -->
    <!-- <joint name="joint3" type="revolute">
      <parent>link3</parent>
      <child>connection2</child>
      <pose>0 0 0 0 0 0</pose>
      <axis>
        <xyz>0 1 0</xyz>
        <limit>
          <lower>0.0</lower>
          <upper>1.57</upper>
        </limit>
        <dynamics>
          <damping>0.1</damping>
          <friction>0.1</friction>
        </dynamics>
      </axis>
    </joint> -->

    <!-- link 4 -->
    <!-- <link name="link4">
      <pose>0 0 0.68 0 0 0</pose>
      <visual name="visual">
        <geometry>
          <box>
            <size>.07 .07 .02</size>
          </box>
        </geometry>
      </visual>
      <collision name="collision">
        <geometry>
          <box>
            <size>.07 .07 .02</size>
          </box>
        </geometry>
      </collision>
    </link> -->

    <!-- Joint 4 -->
    <!-- <joint name="joint4" type="revolute">
      <parent>link3</parent>
      <child>link4</child>
      <pose>0 0 0 0 0 0</pose>
      <axis>
        <xyz>0 0 1</xyz>
        <limit>
          <lower>0.0</lower>
          <upper>1.57</upper>
        </limit>
        <dynamics>
          <damping>0.1</damping>
          <friction>0.1</friction>
        </dynamics>
      </axis>
    </joint> -->

    <!-- link 5 -->
    <!-- <link name="link5">
      <pose>0 0 0.72 1.5708 0 0</pose>
      <visual name="visual">
        <geometry>
          <cylinder>
            <radius>.03</radius>
            <length>.07</length>
          </cylinder>
        </geometry>
      </visual>
      <collision name="collision">
        <geometry>
          <cylinder>
            <radius>.03</radius>
            <length>.07</length>
          </cylinder>
        </geometry>
      </collision>
    </link> -->

    <!-- Joint 5 -->
    <!-- <joint name="joint5" type="revolute">
      <parent>link4</parent>
      <child>link5</child>
      <pose>0 0 0 0 0 0</pose>
      <axis>
        <xyz>0 1 0</xyz>
        <limit>
          <lower>0.0</lower>
          <upper>1.57</upper>
        </limit>
        <dynamics>
          <damping>0.1</damping>
          <friction>0.1</friction>
        </dynamics>
      </axis>
    </joint> -->

    <!-- link 6-->
    <!-- <link name="link6">
      <pose>0 0 0.76 0 0 0</pose>
      <visual name="visual">
        <geometry>
          <box>
            <size>.07 .07 .02</size>
          </box>
        </geometry>
      </visual>
      <collision name="collision">
        <geometry>
          <box>
            <size>.07 .07 .02</size>
          </box>
        </geometry>
      </collision>
    </link> -->

    <!-- Joint 6 -->
    <!-- <joint name="joint6" type="revolute">
      <parent>link5</parent>
      <child>link6</child>
      <pose>0 0 0 0 0 0</pose>
      <axis>
        <xyz>0 0 1</xyz>
        <limit>
          <lower>0.0</lower>
          <upper>1.57</upper>
        </limit>
        <dynamics>
          <damping>0.1</damping>
          <friction>0.1</friction>
        </dynamics>
      </axis>
    </joint> -->

    <!-- Gripper link 1 -->
    <!-- <link name="gripper_link_1">
      <pose>0 -.03 0.8 0 0 0</pose>
      <visual name="visual">
        <geometry>
          <box>
            <size>.02 .02 .06</size>
          </box>
        </geometry>
      </visual>
      <collision name="collision">
        <geometry>
          <box>
            <size>.02 .02 .06</size>
          </box>
        </geometry>
      </collision>
    </link> -->

    <!-- Gripper joint 1 -->
    <!-- <joint name="gripper_joint_1" type="revolute">
      <parent>link6</parent>
      <child>gripper_link_1</child>
      <pose>0 0 -.03 0 0 0</pose>
      <axis>
        <xyz>0 1 0</xyz>
      </axis>
    </joint> -->

    <!-- Gripper link 2 -->
    <!-- <link name="gripper_link_2">
      <pose>0 .03 0.8 0 0 0</pose>
      <visual name="visual">
        <geometry>
          <box>
            <size>.02 .02 .06</size>
          </box>
        </geometry>
      </visual>
      <collision name="collision">
        <geometry>
          <box>
            <size>.02 .02 .06</size>
          </box>
        </geometry>
      </collision>
    </link> -->

    <!-- Gripper joint 2 -->
    <!-- <joint name="gripper_joint_2" type="revolute">
      <parent>link6</parent>
      <child>gripper_link_2</child>
      <pose>0 0 -.03 0 0 0</pose>
      <axis>
        <xyz>0 1 0</xyz>
      </axis>
    </joint> -->

    <!-- Camera -->
    <!-- <link name="camera_link">
      <pose>0 0 0 0 0 0</pose>
      <sensor name="camera" type="camera">
        <camera>
          <horizontal_fov>1.047</horizontal_fov>
          <image>
            <width>640</width>
            <height>640</height>
            <format>R8G8B8</format>
          </image>
          <clip>
            <near>0.1</near>
            <far>100</far>
          </clip>
        </camera>
        <always_on>true</always_on>
        <update_rate>30</update_rate>
        <visualize>true</visualize>
      </sensor>
    </link> -->

    <!-- base_link와 camera_link를 연결하는 조인트 정의 -->
    <!-- <joint name="camera_joint" type="fixed">
      <parent>link6</parent>
      <child>camera_link</child>
      <pose>0 0 0.5 0 0 0</pose>
    </joint> -->



    <!-- Joint State Publisher Plugin -->
    <!-- <plugin name="gazebo_ros_joint_state_publisher" filename="libgazebo_ros_joint_state_publisher.so">
    <ros>
      <namespace>/</namespace>
      <remapping>joint_states:=/joint_states</remapping>
    </ros>
    <robotNamespace>my_robot</robotNamespace>
    <joint_name>joint_fl</joint_name>
    <joint_name>joint_rl</joint_name>
    <joint_name>joint_fr</joint_name>
    <joint_name>joint_rr</joint_name>
  </plugin> -->

    <!-- Diff Drive Plugin -->
    <plugin name="diff_drive_front" filename="libgazebo_ros_diff_drive.so">
      <ros>
        <namespace>/</namespace>
        <remapping>cmd_vel:=/cmd_vel</remapping>
      </ros>
      <robotNamespace>my_robot</robotNamespace>
      <left_joint>joint_fl</left_joint>
      <right_joint>joint_fr</right_joint>
      <wheel_separation>0.3</wheel_separation>
      <wheel_diameter>0.2</wheel_diameter>
      <maxTorque>10.0</maxTorque>
      <maxVelocity>10.0</maxVelocity>
      <topic>/cmd_vel</topic>
      <odometryFrame>odom</odometryFrame>
      <odometryTopic>/odom</odometryTopic>
    </plugin>

    <plugin name="diff_drive_rear" filename="libgazebo_ros_diff_drive.so">
      <ros>
        <namespace>/</namespace>
        <remapping>cmd_vel:=/cmd_vel</remapping>
      </ros>
      <robotNamespace>my_robot</robotNamespace>
      <left_joint>joint_rl</left_joint>
      <right_joint>joint_rr</right_joint>
      <wheel_separation>0.3</wheel_separation>
      <wheel_diameter>0.2</wheel_diameter>
      <maxTorque>10.0</maxTorque>
      <maxVelocity>10.0</maxVelocity>
      <topic>/cmd_vel</topic>
      <odometryFrame>odom</odometryFrame>
      <odometryTopic>/odom</odometryTopic>
    </plugin>

    <!-- <plugin name="gazebo_ros_control" filename="libgazebo_ros_control.so">
      <robotNamespace>/</robotNamespace>
    </plugin> -->

  </model>
</sdf>

